<?xml version="1.0"?>

<sdf version='1.6'>
  <model name='Trolley'>

    <link name='base_footprint'>
      <pose frame=''>0 0 0 0 -0 0</pose>
      <inertial>
        <pose frame=''>0.0 0 0.0 0 -0 0</pose>
        <mass>10</mass>
        <inertia>
          <ixx>0.0594508</ixx>
          <ixy>0</ixy>
          <ixz>-2.77556e-17</ixz>
          <iyy>0.150753</iyy>
          <iyz>0</iyz>
          <izz>0.172704</izz>
        </inertia>
      </inertial>
      <collision name='base_footprint_fixed_joint_lump__base_link_collision'>
        <pose frame=''>-0.11 0 0.151 0 -0 0</pose>
        <geometry>
          <box>
            <size>0.398 0.268 0.16</size>
          </box>
        </geometry>
      </collision>
 
      <collision name='base_footprint_fixed_joint_lump__center_caster_wheel_collision'>
        <pose frame=''>-1.0 0.0 0.04 0 -0 0</pose>
        <geometry>
          <sphere>
            <radius>0.04</radius>
          </sphere>
        </geometry>
        <surface>
          <contact>
            <ode>
              <kp>1e+08</kp>
              <min_depth>0.005</min_depth>
            </ode>
          </contact>
          <friction>
            <ode>
              <mu>0</mu>
              <mu2>0</mu2>
            </ode>
          </friction>
        </surface>
      </collision>
	  
      <visual name='base_footprint_fixed_joint_lump__base_link_visual'>
        <pose frame=''>0.0 0.0 0.0 0 0 1.5708</pose>
        <geometry>
          <mesh>
            <scale>1 1 1</scale>
            <uri>model://Trolley/meshes/Trolley.dae</uri>
          </mesh>
        </geometry>
      </visual>
	  
      <visual name='base_footprint_fixed_joint_lump__base_link_visual_1'>
        <pose frame=''> -0.9 0.0 0.20 0 -0 -3.14159</pose>
        <geometry>
          <mesh>
            <scale>2.2 1 2.2</scale>
            <uri>model://Trolley/meshes/caster_wheel.dae</uri>
          </mesh>
        </geometry>
      </visual>
	  
      <gravity>1</gravity>
      <velocity_decay/>
    </link>
	
	
	
    <link name='left_wheel'>
      <pose frame=''>-0.22 0.35 0.08 0 -0 1.5708</pose>
      <inertial>
        <pose frame=''>0 0 0 3.14159 1.57079 3.14159</pose>
        <mass>3.34</mass>
        <inertia>
          <ixx>0.00904583</ixx>
          <ixy>0</ixy>
          <ixz>0</ixz>
          <iyy>0.00904583</iyy>
          <iyz>0</iyz>
          <izz>0.0167</izz>
        </inertia>
      </inertial>
      <collision name='left_wheel_collision'>
        <pose frame=''>0 0 0 3.14159 1.57079 3.14159</pose>
        <geometry>
          <sphere>
            <radius>0.1</radius>
          </sphere>
        </geometry>
        <surface>
          <contact>
            <ode>
            <!--
              <kp>1e+08</kp>
              <min_depth>0.005</min_depth>
              -->
              <kp>10000000.0</kp>
              <kd>1.0</kd>
            </ode>
          </contact>
          <friction>
            <ode>
              <mu>1</mu>
              <mu2>1</mu2>
              <fdir1>0 0 1</fdir1>
            </ode>
          </friction>
        </surface>
      </collision>
      <visual name='left_wheel_visual'>
        <pose frame=''>-0.071 0 0 0 -0 0</pose>
        <geometry>
          <mesh>
            <scale> 0.5 0.8 0.8</scale>
            <uri>model://Trolley/meshes/front_wheel.dae</uri>
          </mesh>
        </geometry>
      </visual>
	  
	 <visual name="visual">
        <cast_shadows>false</cast_shadows>
	<pose frame=''> -0.35 0.06 0.4 1.5708 0 0</pose>
        <geometry>
          <plane>
            <normal>0 0 1</normal>
            <size>0.15 0.15</size>
          </plane>
        </geometry>
        <material>
          <script>
                  <uri>model://Trolley/materials/scripts/AprilTag.material</uri>
                  <uri>model://Trolley/materials/textures/AprilTag.jpeg</uri>
                  <name>Trolley/AprilTag</name>
          </script>
        </material>
      </visual>
	  
      <gravity>1</gravity>
      <velocity_decay/>
    </link>
	
	
    <joint name='joint_tire_left' type='revolute'>
      <child>left_wheel</child>
      <parent>base_footprint</parent>
      <axis>
        <xyz>0 1 0</xyz>
        <limit>
          <lower>-1e+16</lower>
          <upper>1e+16</upper>
        </limit>
        <dynamics>
          <spring_reference>0</spring_reference>
          <spring_stiffness>0</spring_stiffness>
        </dynamics>
        <use_parent_model_frame>1</use_parent_model_frame>
      </axis>
    </joint>
	
	
    <link name='right_wheel'>
      <pose frame=''>-0.22 -0.35 0.08 0 -0 1.5708</pose>
      <inertial>
        <pose frame=''>0 0 0 3.14159 1.57079 3.14159</pose>
        <mass>3.34</mass>
        <inertia>
          <ixx>0.00904583</ixx>
          <ixy>0</ixy>
          <ixz>0</ixz>
          <iyy>0.00904583</iyy>
          <iyz>0</iyz>
          <izz>0.0167</izz>
        </inertia>
      </inertial>
      <collision name='right_wheel_collision'>
        <pose frame=''>0 0 0 3.14159 1.57079 3.14159</pose>
        <geometry>
          <sphere>
            <radius>0.1</radius>
          </sphere>
        </geometry>
        <surface>
          <contact>
            <ode>
            <!--
              <kp>1e+08</kp>
              <min_depth>0.005</min_depth>
              -->
              <kp>10000000.0</kp>
              <kd>1.0</kd>
            </ode>
          </contact>
          <friction>
            <ode>
              <mu>1</mu>
              <mu2>1</mu2>
              <fdir1>0 0 1</fdir1>
            </ode>
          </friction>
        </surface>
      </collision>
      <visual name='right_wheel_visual'>
        <pose frame=''>0.071 0 0 -3.14159 0 -3.14159</pose>
        <geometry>
          <mesh>
            <scale>0.5 0.8 0.8</scale>
            <uri>model://Trolley/meshes/front_wheel.dae</uri>
          </mesh>
        </geometry>
      </visual>
      <gravity>1</gravity>
      <velocity_decay/>
    </link>
	
	
    <joint name='joint_tire_right' type='revolute'>
      <child>right_wheel</child>
      <parent>base_footprint</parent>
      <axis>
        <xyz>0 1 0</xyz>
        <limit>
          <lower>-1e+16</lower>
          <upper>1e+16</upper>
        </limit>
        <dynamics>
          <spring_reference>0</spring_reference>
          <spring_stiffness>0</spring_stiffness>
        </dynamics>
        <use_parent_model_frame>1</use_parent_model_frame>
      </axis>
    </joint>
    <static>0</static>

  </model>
</sdf>
