<sdf version="1.7">
  <world name="world">
    <scene>
      <ambient>0.8 0.8 0.8 1.0</ambient>
      <background>0 0 0</background>
      <grid>false</grid>
    </scene>
    <include>
      <uri>model://sun</uri>
    </include>

    <include>
      <name>mbc_building_L1</name>
      <uri>model://mbc_building_L1</uri>
      <pose>0 0 0.0 0 0 0</pose>
    </include>
    
    <gui>
      <camera name="gui_camera">
        <pose>5.876012603063672 -39.07439102613174 10 0 0.6 1.57</pose>
      </camera>
      <plugin name="toggle_charging" filename="libtoggle_charging.so" />
      <plugin name="toggle_floors" filename="libtoggle_floors.so">
        <floor name="L1" model_name="building_L1">
          <model name="OpenRobotics/Sofa" />
          <model name="OpenRobotics/Sofa_2" />
          <model name="OpenRobotics/Cafe table" />
          <model name="OpenRobotics/Cafe table_2" />
          <model name="OpenRobotics/CoffeeTable" />
          <model name="OpenRobotics/CoffeeTable_2" />
          <model name="OpenRobotics/CoffeeTable_3" />
          <model name="OpenRobotics/CoffeeTable_4" />
          <model name="OpenRobotics/CoffeeTable_5" />
          <model name="OpenRobotics/CoffeeTable_6" />
          <model name="OpenRobotics/ConfTable" />
          <model name="OpenRobotics/Desk" />
          <model name="OpenRobotics/Desk_2" />
          <model name="OpenRobotics/KitchenCountertop" />
          <model name="OpenRobotics/ConfTable_2" />
          <model name="OpenRobotics/CoffeeTable_7" />
          <model name="OpenRobotics/CoffeeTable_8" />
          <model name="OpenRobotics/CoffeeTable_9" />
          <model name="OpenRobotics/Desk_3" />
          <model name="OpenRobotics/Desk_4" />
          <model name="OpenRobotics/Desk_5" />
          <model name="OpenRobotics/Desk_6" />
          <model name="OpenRobotics/Desk_7" />
          <model name="meet_rm1_door" />
          <model name="meet_rm2_door" />
          <model name="meet_rm3_door" />
          <model name="office_door" />
          <model name="meet_rm4_door" />
          <model name="meet_rm5_door" />
          <model name="meet_rm6_door" />
          <model name="meet_rm7_door" />
          <model name="meet_rm8_door" />
          <model name="meet_rm9_door" />
          <model name="cargo_lift_door" />
          <model name="board_rm_door" />
          <model name="meeting_rm_door" />
          <model name="office_door_2" />
          <model name="main_door" />
          <model name="cafe_door_1" />
          <model name="cafe_door_2" />
          <model name="stairs_door" />
          <model name="locker_rm_door" />
        </floor>
      </plugin>
    </gui>
    <include>
      <name>OpenRobotics/Sofa</name>
      <uri>model://Sofa</uri>
      <pose>24.656157148709898 -17.950833449799774 0.0 0 0 1.5708</pose>
      <static>True</static>
    </include>
    <include>
      <name>OpenRobotics/Sofa_2</name>
      <uri>model://Sofa</uri>
      <pose>24.678029607988627 -23.60636753645477 0.0 0 0 1.5708</pose>
      <static>True</static>
    </include>
    <include>
      <name>OpenRobotics/Cafe table</name>
      <uri>model://Cafe table</uri>
      <pose>24.678029607988627 -16.858153772516953 0.0 0 0 1.5708</pose>
      <static>True</static>
    </include>
    <include>
      <name>OpenRobotics/Cafe table_2</name>
      <uri>model://Cafe table</uri>
      <pose>24.652885123130464 -22.575915300597007 0.0 0 0 1.5708</pose>
      <static>True</static>
    </include>
    <include>
      <name>OpenRobotics/CoffeeTable</name>
      <uri>model://CoffeeTable</uri>
      <pose>27.93275177287014 -18.39125988387452 0.0 0 0 -2.5458</pose>
      <static>True</static>
    </include>
    <include>
      <name>OpenRobotics/CoffeeTable_2</name>
      <uri>model://CoffeeTable</uri>
      <pose>29.754886810410884 -23.304781106696474 0.0 0 0 1.5708</pose>
      <static>True</static>
    </include>
    <include>
      <name>OpenRobotics/CoffeeTable_3</name>
      <uri>model://CoffeeTable</uri>
      <pose>29.2647904384862 -20.766337766631384 0.0 0 0 1.5708</pose>
      <static>True</static>
    </include>
    <include>
      <name>OpenRobotics/CoffeeTable_4</name>
      <uri>model://CoffeeTable</uri>
      <pose>32.72058004910922 -22.173780409113995 0.0 0 0 1.5708</pose>
      <static>True</static>
    </include>
    <include>
      <name>OpenRobotics/CoffeeTable_5</name>
      <uri>model://CoffeeTable</uri>
      <pose>32.519512603367716 -17.989124992391506 0.0 0 0 1.5708</pose>
      <static>True</static>
    </include>
    <include>
      <name>OpenRobotics/CoffeeTable_6</name>
      <uri>model://CoffeeTable</uri>
      <pose>27.56831886982041 -22.4251073468639 0.0 0 0 1.5708</pose>
      <static>True</static>
    </include>
    <include>
      <name>OpenRobotics/ConfTable</name>
      <uri>model://ConfTable</uri>
      <pose>44.09284394406697 -13.396114887814297 0.0 0 0 1.5708</pose>
      <static>True</static>
    </include>
    <include>
      <name>OpenRobotics/Desk</name>
      <uri>model://Desk</uri>
      <pose>6.686133711052371 -13.124035643686737 0.0 0 0 1.5708</pose>
      <static>True</static>
    </include>
    <include>
      <name>OpenRobotics/Desk_2</name>
      <uri>model://Desk</uri>
      <pose>7.594106070490848 -13.124035643686737 0.0 0 0 1.5708</pose>
      <static>True</static>
    </include>
    <include>
      <name>OpenRobotics/KitchenCountertop</name>
      <uri>model://KitchenCountertop</uri>
      <pose>17.732521544923426 -17.8797921737058 0.0 0 0 1.3094</pose>
      <static>True</static>
    </include>
    <include>
      <name>OpenRobotics/ConfTable_2</name>
      <uri>model://ConfTable</uri>
      <pose>16.922975252239222 -20.890232573030964 0.0 0 0 0.0</pose>
      <static>True</static>
    </include>
    <include>
      <name>OpenRobotics/CoffeeTable_7</name>
      <uri>model://CoffeeTable</uri>
      <pose>12.047598183469386 -21.754224192248603 0.0 0 0 1.5708</pose>
      <static>True</static>
    </include>
    <include>
      <name>OpenRobotics/CoffeeTable_8</name>
      <uri>model://CoffeeTable</uri>
      <pose>13.933935668866015 -21.754224192248603 0.0 0 0 1.5708</pose>
      <static>True</static>
    </include>
    <include>
      <name>OpenRobotics/CoffeeTable_9</name>
      <uri>model://CoffeeTable</uri>
      <pose>19.865499012510227 -21.733265541915486 0.0 0 0 1.5799</pose>
      <static>True</static>
    </include>
    <include>
      <name>OpenRobotics/Desk_3</name>
      <uri>model://Desk</uri>
      <pose>11.837982202430265 -23.829219008351235 0.0 0 0 1.5708</pose>
      <static>True</static>
    </include>
    <include>
      <name>OpenRobotics/Desk_4</name>
      <uri>model://Desk</uri>
      <pose>13.598597263536098 -23.829219008351235 0.0 0 0 1.5708</pose>
      <static>True</static>
    </include>
    <include>
      <name>OpenRobotics/Desk_5</name>
      <uri>model://Desk</uri>
      <pose>16.008959962676567 -23.787301707684993 0.0 0 0 1.5708</pose>
      <static>True</static>
    </include>
    <include>
      <name>OpenRobotics/Desk_6</name>
      <uri>model://Desk</uri>
      <pose>17.790504196407596 -23.829219008351235 0.0 0 0 1.5708</pose>
      <static>True</static>
    </include>
    <include>
      <name>OpenRobotics/Desk_7</name>
      <uri>model://Desk</uri>
      <pose>20.368536098213024 -23.808260358018114 0.0 0 0 1.5708</pose>
      <static>True</static>
    </include>
    <include>
      <name>tinyRobot1</name>
      <uri>model://TinyRobot</uri>
      <pose>22.858547564160936 -12.49798808282204 0.0 0 0 4.7432138953920955</pose>
    </include>
    <include>
      <name>tinyRobot2</name>
      <uri>model://TinyRobot</uri>
      <pose>39.2263396653819 -12.45008680744747 0.0 0 0 4.787100311947599</pose>
    </include>
    <include>
      <name>Locust1</name>
      <uri>model://Locust</uri>
      <pose>26.302369225367293 -11.982747226039198 0.0 0 0 4.692393992003806</pose>
    </include>
    <include>
      <name>Locust2</name>
      <uri>model://Locust</uri>
      <pose>28.191801870095816 -25.216498898614642 0.0 0 0 -3.115722415738105</pose>
    </include>
    <model name="meet_rm1_door">
      <pose>40.22520653720037 -23.99887795630098 0.0 0 0 1.5718276491743395</pose>
      <plugin name="door" filename="libdoor.so">
        <v_max_door>0.5</v_max_door>
        <a_max_door>0.3</a_max_door>
        <a_nom_door>0.15</a_nom_door>
        <dx_min_door>0.01</dx_min_door>
        <f_max_door>500.0</f_max_door>
        <door name="meet_rm1_door" type="SwingDoor" left_joint_name="left_joint" right_joint_name="empty_joint" />
      </plugin>
      <link name="left">
        <pose>0 0 1.11 0 0 0</pose>
        <visual name="left_visual">
          <geometry>
            <box>
              <size>0.9903855057943896 0.03 2.2</size>
            </box>
          </geometry>
          <material>
            <ambient>120 60 0 0.6</ambient>
            <diffuse>120 60 0 0.6</diffuse>
          </material>
        </visual>
        <collision name="left_collision">
          <geometry>
            <box>
              <size>0.9903855057943896 0.03 2.2</size>
            </box>
          </geometry>
          <surface>
            <contact>
              <collide_bitmask>0x02</collide_bitmask>
            </contact>
          </surface>
        </collision>
        <inertial>
          <mass>50.0</mass>
          <inertia>
            <ixx>20.17041666666667</ixx>
            <iyy>24.253597708698372</iyy>
            <izz>4.0906810420317035</izz>
          </inertia>
        </inertial>
      </link>
      <joint name="left_joint" type="revolute">
        <parent>world</parent>
        <child>left</child>
        <axis>
          <xyz>0 0 1</xyz>
          <limit>
            <lower>-1.57</lower>
            <upper>0</upper>
          </limit>
        </axis>
        <pose>0.5001927528971948 0 0 0 0 0</pose>
      </joint>
    </model>
    <model name="meet_rm2_door">
      <pose>40.22469067731173 -20.87057094184645 0.0 0 0 1.5363231228946317</pose>
      <plugin name="door" filename="libdoor.so">
        <v_max_door>0.5</v_max_door>
        <a_max_door>0.3</a_max_door>
        <a_nom_door>0.15</a_nom_door>
        <dx_min_door>0.01</dx_min_door>
        <f_max_door>500.0</f_max_door>
        <door name="meet_rm2_door" type="SwingDoor" left_joint_name="left_joint" right_joint_name="empty_joint" />
      </plugin>
      <link name="left">
        <pose>0 0 1.11 0 0 0</pose>
        <visual name="left_visual">
          <geometry>
            <box>
              <size>0.9803909095176097 0.03 2.2</size>
            </box>
          </geometry>
          <material>
            <ambient>120 60 0 0.6</ambient>
            <diffuse>120 60 0 0.6</diffuse>
          </material>
        </visual>
        <collision name="left_collision">
          <geometry>
            <box>
              <size>0.9803909095176097 0.03 2.2</size>
            </box>
          </geometry>
          <surface>
            <contact>
              <collide_bitmask>0x02</collide_bitmask>
            </contact>
          </surface>
        </collision>
        <inertial>
          <mass>50.0</mass>
          <inertia>
            <ixx>20.17041666666667</ixx>
            <iyy>24.171526397769863</iyy>
            <izz>4.008609731103192</izz>
          </inertia>
        </inertial>
      </link>
      <joint name="left_joint" type="revolute">
        <parent>world</parent>
        <child>left</child>
        <axis>
          <xyz>0 0 1</xyz>
          <limit>
            <lower>-1.57</lower>
            <upper>0</upper>
          </limit>
        </axis>
        <pose>0.49519545475880483 0 0 0 0 0</pose>
      </joint>
    </model>
    <model name="meet_rm3_door">
      <pose>40.22469067731172 -17.696352397302135 0.0 0 0 1.5707963267948966</pose>
      <plugin name="door" filename="libdoor.so">
        <v_max_door>0.5</v_max_door>
        <a_max_door>0.3</a_max_door>
        <a_nom_door>0.15</a_nom_door>
        <dx_min_door>0.01</dx_min_door>
        <f_max_door>500.0</f_max_door>
        <door name="meet_rm3_door" type="SwingDoor" left_joint_name="left_joint" right_joint_name="empty_joint" />
      </plugin>
      <link name="left">
        <pose>0 0 1.11 0 0 0</pose>
        <visual name="left_visual">
          <geometry>
            <box>
              <size>1.0139376624068193 0.03 2.2</size>
            </box>
          </geometry>
          <material>
            <ambient>120 60 0 0.6</ambient>
            <diffuse>120 60 0 0.6</diffuse>
          </material>
        </visual>
        <collision name="left_collision">
          <geometry>
            <box>
              <size>1.0139376624068193 0.03 2.2</size>
            </box>
          </geometry>
          <surface>
            <contact>
              <collide_bitmask>0x02</collide_bitmask>
            </contact>
          </surface>
        </collision>
        <inertial>
          <mass>50.0</mass>
          <inertia>
            <ixx>20.17041666666667</ixx>
            <iyy>24.450289930195858</iyy>
            <izz>4.2873732635291875</izz>
          </inertia>
        </inertial>
      </link>
      <joint name="left_joint" type="revolute">
        <parent>world</parent>
        <child>left</child>
        <axis>
          <xyz>0 0 1</xyz>
          <limit>
            <lower>-1.57</lower>
            <upper>0</upper>
          </limit>
        </axis>
        <pose>0.5119688312034096 0 0 0 0 0</pose>
      </joint>
    </model>
    <model name="office_door">
      <pose>41.16495586577963 -11.327870466825992 0.0 0 0 3.141592653589793</pose>
      <link name="right">
        <pose>-0.4227029621861522 0 1.11 0 0 0</pose>
        <visual name="right_visual">
          <geometry>
            <box>
              <size>0.8354059243723044 0.03 2.2</size>
            </box>
          </geometry>
          <material>
            <ambient>120 60 0 0.6</ambient>
            <diffuse>120 60 0 0.6</diffuse>
          </material>
        </visual>
        <collision name="right_collision">
          <geometry>
            <box>
              <size>0.8354059243723044 0.03 2.2</size>
            </box>
          </geometry>
          <surface>
            <contact>
              <collide_bitmask>0x02</collide_bitmask>
            </contact>
          </surface>
        </collision>
        <inertial>
          <mass>50.0</mass>
          <inertia>
            <ixx>20.17041666666667</ixx>
            <iyy>23.074596076984776</iyy>
            <izz>2.911679410318102</izz>
          </inertia>
        </inertial>
      </link>
      <joint name="right_joint" type="revolute">
        <parent>world</parent>
        <child>right</child>
        <axis>
          <xyz>0 0 1</xyz>
          <limit>
            <lower>0</lower>
            <upper>1.57</upper>
          </limit>
        </axis>
        <pose>-0.4227029621861522 0 0 0 0 0</pose>
      </joint>
      <link name="left">
        <pose>0.4227029621861522 0 1.11 0 0 0</pose>
        <visual name="left_visual">
          <geometry>
            <box>
              <size>0.8354059243723044 0.03 2.2</size>
            </box>
          </geometry>
          <material>
            <ambient>120 60 0 0.6</ambient>
            <diffuse>120 60 0 0.6</diffuse>
          </material>
        </visual>
        <collision name="left_collision">
          <geometry>
            <box>
              <size>0.8354059243723044 0.03 2.2</size>
            </box>
          </geometry>
          <surface>
            <contact>
              <collide_bitmask>0x02</collide_bitmask>
            </contact>
          </surface>
        </collision>
        <inertial>
          <mass>50.0</mass>
          <inertia>
            <ixx>20.17041666666667</ixx>
            <iyy>23.074596076984776</iyy>
            <izz>2.911679410318102</izz>
          </inertia>
        </inertial>
      </link>
      <joint name="left_joint" type="revolute">
        <parent>world</parent>
        <child>left</child>
        <axis>
          <xyz>0 0 1</xyz>
          <limit>
            <lower>-1.57</lower>
            <upper>0</upper>
          </limit>
        </axis>
        <pose>0.4227029621861522 0 0 0 0 0</pose>
      </joint>
      <plugin name="door" filename="libdoor.so">
        <v_max_door>0.5</v_max_door>
        <a_max_door>0.3</a_max_door>
        <a_nom_door>0.15</a_nom_door>
        <dx_min_door>0.01</dx_min_door>
        <f_max_door>500.0</f_max_door>
        <door name="office_door" type="DoubleSwingDoor" left_joint_name="left_joint" right_joint_name="right_joint" />
      </plugin>
    </model>
    <model name="meet_rm4_door">
      <pose>39.31114703107583 -13.625878882218661 0.0 0 0 0.04995839572194276</pose>
      <plugin name="door" filename="libdoor.so">
        <v_max_door>0.5</v_max_door>
        <a_max_door>0.3</a_max_door>
        <a_nom_door>0.15</a_nom_door>
        <dx_min_door>0.01</dx_min_door>
        <f_max_door>500.0</f_max_door>
        <door name="meet_rm4_door" type="SwingDoor" left_joint_name="left_joint" right_joint_name="empty_joint" />
      </plugin>
      <link name="left">
        <pose>0 0 1.11 0 0 0</pose>
        <visual name="left_visual">
          <geometry>
            <box>
              <size>0.9858203116031377 0.03 2.2</size>
            </box>
          </geometry>
          <material>
            <ambient>120 60 0 0.6</ambient>
            <diffuse>120 60 0 0.6</diffuse>
          </material>
        </visual>
        <collision name="left_collision">
          <geometry>
            <box>
              <size>0.9858203116031377 0.03 2.2</size>
            </box>
          </geometry>
          <surface>
            <contact>
              <collide_bitmask>0x02</collide_bitmask>
            </contact>
          </surface>
        </collision>
        <inertial>
          <mass>50.0</mass>
          <inertia>
            <ixx>20.17041666666667</ixx>
            <iyy>24.216007028205453</iyy>
            <izz>4.053090361538781</izz>
          </inertia>
        </inertial>
      </link>
      <joint name="left_joint" type="revolute">
        <parent>world</parent>
        <child>left</child>
        <axis>
          <xyz>0 0 1</xyz>
          <limit>
            <lower>-1.57</lower>
            <upper>0</upper>
          </limit>
        </axis>
        <pose>0.49791015580156883 0 0 0 0 0</pose>
      </joint>
    </model>
    <model name="meet_rm5_door">
      <pose>42.0231698542444 -14.62630807255704 0.0 0 0 -1.5587508827883254</pose>
      <plugin name="door" filename="libdoor.so">
        <v_max_door>0.5</v_max_door>
        <a_max_door>0.3</a_max_door>
        <a_nom_door>0.15</a_nom_door>
        <dx_min_door>0.01</dx_min_door>
        <f_max_door>500.0</f_max_door>
        <door name="meet_rm5_door" type="SwingDoor" left_joint_name="left_joint" right_joint_name="empty_joint" />
      </plugin>
      <link name="left">
        <pose>0 0 1.11 0 0 0</pose>
        <visual name="left_visual">
          <geometry>
            <box>
              <size>1.1377683456763723 0.03 2.2</size>
            </box>
          </geometry>
          <material>
            <ambient>120 60 0 0.6</ambient>
            <diffuse>120 60 0 0.6</diffuse>
          </material>
        </visual>
        <collision name="left_collision">
          <geometry>
            <box>
              <size>1.1377683456763723 0.03 2.2</size>
            </box>
          </geometry>
          <surface>
            <contact>
              <collide_bitmask>0x02</collide_bitmask>
            </contact>
          </surface>
        </collision>
        <inertial>
          <mass>50.0</mass>
          <inertia>
            <ixx>20.17041666666667</ixx>
            <iyy>25.56048670176313</iyy>
            <izz>5.397570035096455</izz>
          </inertia>
        </inertial>
      </link>
      <joint name="left_joint" type="revolute">
        <parent>world</parent>
        <child>left</child>
        <axis>
          <xyz>0 0 1</xyz>
          <limit>
            <lower>-1.57</lower>
            <upper>0</upper>
          </limit>
        </axis>
        <pose>0.5738841728381862 0 0 0 0 0</pose>
      </joint>
    </model>
    <model name="meet_rm6_door">
      <pose>41.670542773217754 -17.530142341179353 0.0 0 0 -1.5707963267948966</pose>
      <plugin name="door" filename="libdoor.so">
        <v_max_door>0.5</v_max_door>
        <a_max_door>0.3</a_max_door>
        <a_nom_door>0.15</a_nom_door>
        <dx_min_door>0.01</dx_min_door>
        <f_max_door>500.0</f_max_door>
        <door name="meet_rm6_door" type="SwingDoor" left_joint_name="left_joint" right_joint_name="empty_joint" />
      </plugin>
      <link name="left">
        <pose>0 0 1.11 0 0 0</pose>
        <visual name="left_visual">
          <geometry>
            <box>
              <size>1.1930147380379077 0.03 2.2</size>
            </box>
          </geometry>
          <material>
            <ambient>120 60 0 0.6</ambient>
            <diffuse>120 60 0 0.6</diffuse>
          </material>
        </visual>
        <collision name="left_collision">
          <geometry>
            <box>
              <size>1.1930147380379077 0.03 2.2</size>
            </box>
          </geometry>
          <surface>
            <contact>
              <collide_bitmask>0x02</collide_bitmask>
            </contact>
          </surface>
        </collision>
        <inertial>
          <mass>50.0</mass>
          <inertia>
            <ixx>20.17041666666667</ixx>
            <iyy>26.09701735489858</iyy>
            <izz>5.934100688231907</izz>
          </inertia>
        </inertial>
      </link>
      <joint name="left_joint" type="revolute">
        <parent>world</parent>
        <child>left</child>
        <axis>
          <xyz>0 0 1</xyz>
          <limit>
            <lower>-1.57</lower>
            <upper>0</upper>
          </limit>
        </axis>
        <pose>0.6015073690189539 0 0 0 0 0</pose>
      </joint>
    </model>
    <model name="meet_rm7_door">
      <pose>42.002432286720705 -20.24732376323442 0.0 0 0 -1.5707963267948966</pose>
      <plugin name="door" filename="libdoor.so">
        <v_max_door>0.5</v_max_door>
        <a_max_door>0.3</a_max_door>
        <a_nom_door>0.15</a_nom_door>
        <dx_min_door>0.01</dx_min_door>
        <f_max_door>500.0</f_max_door>
        <door name="meet_rm7_door" type="SwingDoor" left_joint_name="left_joint" right_joint_name="empty_joint" />
      </plugin>
      <link name="left">
        <pose>0 0 1.11 0 0 0</pose>
        <visual name="left_visual">
          <geometry>
            <box>
              <size>1.151539602990512 0.03 2.2</size>
            </box>
          </geometry>
          <material>
            <ambient>120 60 0 0.6</ambient>
            <diffuse>120 60 0 0.6</diffuse>
          </material>
        </visual>
        <collision name="left_collision">
          <geometry>
            <box>
              <size>1.151539602990512 0.03 2.2</size>
            </box>
          </geometry>
          <surface>
            <contact>
              <collide_bitmask>0x02</collide_bitmask>
            </contact>
          </surface>
        </collision>
        <inertial>
          <mass>50.0</mass>
          <inertia>
            <ixx>20.17041666666667</ixx>
            <iyy>25.691847738564782</iyy>
            <izz>5.528931071898109</izz>
          </inertia>
        </inertial>
      </link>
      <joint name="left_joint" type="revolute">
        <parent>world</parent>
        <child>left</child>
        <axis>
          <xyz>0 0 1</xyz>
          <limit>
            <lower>-1.57</lower>
            <upper>0</upper>
          </limit>
        </axis>
        <pose>0.580769801495256 0 0 0 0 0</pose>
      </joint>
    </model>
    <model name="meet_rm8_door">
      <pose>41.58268446475382 -23.00882491915143 0.0 0 0 -1.5827017777277603</pose>
      <plugin name="door" filename="libdoor.so">
        <v_max_door>0.5</v_max_door>
        <a_max_door>0.3</a_max_door>
        <a_nom_door>0.15</a_nom_door>
        <dx_min_door>0.01</dx_min_door>
        <f_max_door>500.0</f_max_door>
        <door name="meet_rm8_door" type="SwingDoor" left_joint_name="left_joint" right_joint_name="empty_joint" />
      </plugin>
      <link name="left">
        <pose>0 0 1.11 0 0 0</pose>
        <visual name="left_visual">
          <geometry>
            <box>
              <size>1.1116473211203852 0.03 2.2</size>
            </box>
          </geometry>
          <material>
            <ambient>120 60 0 0.6</ambient>
            <diffuse>120 60 0 0.6</diffuse>
          </material>
        </visual>
        <collision name="left_collision">
          <geometry>
            <box>
              <size>1.1116473211203852 0.03 2.2</size>
            </box>
          </geometry>
          <surface>
            <contact>
              <collide_bitmask>0x02</collide_bitmask>
            </contact>
          </surface>
        </collision>
        <inertial>
          <mass>50.0</mass>
          <inertia>
            <ixx>20.17041666666667</ixx>
            <iyy>25.315665693975543</iyy>
            <izz>5.152749027308871</izz>
          </inertia>
        </inertial>
      </link>
      <joint name="left_joint" type="revolute">
        <parent>world</parent>
        <child>left</child>
        <axis>
          <xyz>0 0 1</xyz>
          <limit>
            <lower>-1.57</lower>
            <upper>0</upper>
          </limit>
        </axis>
        <pose>0.5608236605601926 0 0 0 0 0</pose>
      </joint>
    </model>
    <model name="meet_rm9_door">
      <pose>41.856399721671096 -24.591055630762362 0.0 0 0 -1.5707963267948966</pose>
      <plugin name="door" filename="libdoor.so">
        <v_max_door>0.5</v_max_door>
        <a_max_door>0.3</a_max_door>
        <a_nom_door>0.15</a_nom_door>
        <dx_min_door>0.01</dx_min_door>
        <f_max_door>500.0</f_max_door>
        <door name="meet_rm9_door" type="SwingDoor" left_joint_name="left_joint" right_joint_name="empty_joint" />
      </plugin>
      <link name="left">
        <pose>0 0 1.11 0 0 0</pose>
        <visual name="left_visual">
          <geometry>
            <box>
              <size>1.044800822602008 0.03 2.2</size>
            </box>
          </geometry>
          <material>
            <ambient>120 60 0 0.6</ambient>
            <diffuse>120 60 0 0.6</diffuse>
          </material>
        </visual>
        <collision name="left_collision">
          <geometry>
            <box>
              <size>1.044800822602008 0.03 2.2</size>
            </box>
          </geometry>
          <surface>
            <contact>
              <collide_bitmask>0x02</collide_bitmask>
            </contact>
          </surface>
        </collision>
        <inertial>
          <mass>50.0</mass>
          <inertia>
            <ixx>20.17041666666667</ixx>
            <iyy>24.715036495457642</iyy>
            <izz>4.552119828790969</izz>
          </inertia>
        </inertial>
      </link>
      <joint name="left_joint" type="revolute">
        <parent>world</parent>
        <child>left</child>
        <axis>
          <xyz>0 0 1</xyz>
          <limit>
            <lower>-1.57</lower>
            <upper>0</upper>
          </limit>
        </axis>
        <pose>0.527400411301004 0 0 0 0 0</pose>
      </joint>
    </model>
    <model name="cargo_lift_door">
      <pose>31.286902246575302 -11.408315131747347 0.0 0 0 -0.008697690572347636</pose>
      <plugin name="door" filename="libdoor.so">
        <v_max_door>0.5</v_max_door>
        <a_max_door>0.3</a_max_door>
        <a_nom_door>0.15</a_nom_door>
        <dx_min_door>0.01</dx_min_door>
        <f_max_door>500.0</f_max_door>
        <door name="cargo_lift_door" type="SwingDoor" left_joint_name="left_joint" right_joint_name="empty_joint" />
      </plugin>
      <link name="left">
        <pose>0 0 1.11 0 0 0</pose>
        <visual name="left_visual">
          <geometry>
            <box>
              <size>1.3524522390858726 0.03 2.2</size>
            </box>
          </geometry>
          <material>
            <ambient>120 60 0 0.6</ambient>
            <diffuse>120 60 0 0.6</diffuse>
          </material>
        </visual>
        <collision name="left_collision">
          <geometry>
            <box>
              <size>1.3524522390858726 0.03 2.2</size>
            </box>
          </geometry>
          <surface>
            <contact>
              <collide_bitmask>0x02</collide_bitmask>
            </contact>
          </surface>
        </collision>
        <inertial>
          <mass>50.0</mass>
          <inertia>
            <ixx>20.17041666666667</ixx>
            <iyy>27.788029412534964</iyy>
            <izz>7.625112745868293</izz>
          </inertia>
        </inertial>
      </link>
      <joint name="left_joint" type="revolute">
        <parent>world</parent>
        <child>left</child>
        <axis>
          <xyz>0 0 1</xyz>
          <limit>
            <lower>-1.57</lower>
            <upper>0</upper>
          </limit>
        </axis>
        <pose>0.6812261195429363 0 0 0 0 0</pose>
      </joint>
    </model>
    <model name="board_rm_door">
      <pose>0.7314745832506351 -14.57246703903602 0.0 0 0 -1.6373130544308767</pose>
      <plugin name="door" filename="libdoor.so">
        <v_max_door>0.5</v_max_door>
        <a_max_door>0.3</a_max_door>
        <a_nom_door>0.15</a_nom_door>
        <dx_min_door>0.01</dx_min_door>
        <f_max_door>500.0</f_max_door>
        <door name="board_rm_door" type="SwingDoor" left_joint_name="left_joint" right_joint_name="empty_joint" />
      </plugin>
      <link name="left">
        <pose>0 0 1.11 0 0 0</pose>
        <visual name="left_visual">
          <geometry>
            <box>
              <size>0.9049184073394696 0.03 2.2</size>
            </box>
          </geometry>
          <material>
            <ambient>120 60 0 0.6</ambient>
            <diffuse>120 60 0 0.6</diffuse>
          </material>
        </visual>
        <collision name="left_collision">
          <geometry>
            <box>
              <size>0.9049184073394696 0.03 2.2</size>
            </box>
          </geometry>
          <surface>
            <contact>
              <collide_bitmask>0x02</collide_bitmask>
            </contact>
          </surface>
        </collision>
        <inertial>
          <mass>50.0</mass>
          <inertia>
            <ixx>20.17041666666667</ixx>
            <iyy>23.57865551642418</iyy>
            <izz>3.4157388497575094</izz>
          </inertia>
        </inertial>
      </link>
      <joint name="left_joint" type="revolute">
        <parent>world</parent>
        <child>left</child>
        <axis>
          <xyz>0 0 1</xyz>
          <limit>
            <lower>-1.57</lower>
            <upper>0</upper>
          </limit>
        </axis>
        <pose>0.4574592036697348 0 0 0 0 0</pose>
      </joint>
    </model>
    <model name="meeting_rm_door">
      <pose>0.7524332335837549 -12.92640235091824 0.0 0 0 1.5535450574440104</pose>
      <plugin name="door" filename="libdoor.so">
        <v_max_door>0.5</v_max_door>
        <a_max_door>0.3</a_max_door>
        <a_nom_door>0.15</a_nom_door>
        <dx_min_door>0.01</dx_min_door>
        <f_max_door>500.0</f_max_door>
        <door name="meeting_rm_door" type="SwingDoor" left_joint_name="left_joint" right_joint_name="empty_joint" />
      </plugin>
      <link name="left">
        <pose>0 0 1.11 0 0 0</pose>
        <visual name="left_visual">
          <geometry>
            <box>
              <size>1.0853482696837398 0.03 2.2</size>
            </box>
          </geometry>
          <material>
            <ambient>120 60 0 0.6</ambient>
            <diffuse>120 60 0 0.6</diffuse>
          </material>
        </visual>
        <collision name="left_collision">
          <geometry>
            <box>
              <size>1.0853482696837398 0.03 2.2</size>
            </box>
          </geometry>
          <surface>
            <contact>
              <collide_bitmask>0x02</collide_bitmask>
            </contact>
          </surface>
        </collision>
        <inertial>
          <mass>50.0</mass>
          <inertia>
            <ixx>20.17041666666667</ixx>
            <iyy>25.0749202771062</iyy>
            <izz>4.912003610439532</izz>
          </inertia>
        </inertial>
      </link>
      <joint name="left_joint" type="revolute">
        <parent>world</parent>
        <child>left</child>
        <axis>
          <xyz>0 0 1</xyz>
          <limit>
            <lower>-1.57</lower>
            <upper>0</upper>
          </limit>
        </axis>
        <pose>0.5476741348418699 0 0 0 0 0</pose>
      </joint>
    </model>
    <model name="office_door_2">
      <pose>2.8200881004136047 -11.30250489915841 0.0 0 0 0.031236025893627936</pose>
      <link name="right">
        <pose>0 0 1.11 0 0 0</pose>
        <visual name="right_visual">
          <geometry>
            <box>
              <size>1.199087390577288 0.03 2.2</size>
            </box>
          </geometry>
          <material>
            <ambient>120 60 0 0.6</ambient>
            <diffuse>120 60 0 0.6</diffuse>
          </material>
        </visual>
        <collision name="right_collision">
          <geometry>
            <box>
              <size>1.199087390577288 0.03 2.2</size>
            </box>
          </geometry>
          <surface>
            <contact>
              <collide_bitmask>0x02</collide_bitmask>
            </contact>
          </surface>
        </collision>
        <inertial>
          <mass>50.0</mass>
          <inertia>
            <ixx>20.17041666666667</ixx>
            <iyy>26.157544042672715</iyy>
            <izz>5.994627376006041</izz>
          </inertia>
        </inertial>
      </link>
      <joint name="right_joint" type="prismatic">
        <parent>world</parent>
        <child>right</child>
        <axis>
          <xyz>1 0 0</xyz>
          <limit>
            <lower>0.0</lower>
            <upper>1.209087390577288</upper>
            <effort>500.0</effort>
          </limit>
        </axis>
      </joint>
      <plugin name="door" filename="libdoor.so">
        <v_max_door>0.2</v_max_door>
        <a_max_door>0.2</a_max_door>
        <a_nom_door>0.08</a_nom_door>
        <dx_min_door>0.001</dx_min_door>
        <f_max_door>100.0</f_max_door>
        <door name="office_door_2" type="SlidingDoor" left_joint_name="empty_joint" right_joint_name="right_joint" />
      </plugin>
    </model>
    <model name="main_door">
      <pose>16.30012602268415 -11.296535663304041 0.0 0 0 3.1296228831430666</pose>
      <link name="left">
        <pose>-0.7425155903545689 0 1.11 0 0 0</pose>
        <visual name="left_visual">
          <geometry>
            <box>
              <size>1.4750311807091379 0.03 2.2</size>
            </box>
          </geometry>
          <material>
            <ambient>120 60 0 0.6</ambient>
            <diffuse>120 60 0 0.6</diffuse>
          </material>
        </visual>
        <collision name="left_collision">
          <geometry>
            <box>
              <size>1.4750311807091379 0.03 2.2</size>
            </box>
          </geometry>
          <surface>
            <contact>
              <collide_bitmask>0x02</collide_bitmask>
            </contact>
          </surface>
        </collision>
        <inertial>
          <mass>50.0</mass>
          <inertia>
            <ixx>20.17041666666667</ixx>
            <iyy>29.232154100267476</iyy>
            <izz>9.069237433600806</izz>
          </inertia>
        </inertial>
      </link>
      <joint name="left_joint" type="prismatic">
        <parent>world</parent>
        <child>left</child>
        <axis>
          <xyz>1 0 0</xyz>
          <limit>
            <lower>-1.4850311807091379</lower>
            <upper>0.0</upper>
            <effort>500.0</effort>
          </limit>
        </axis>
      </joint>
      <link name="right">
        <pose>0.7425155903545689 0 1.11 0 0 0</pose>
        <visual name="right_visual">
          <geometry>
            <box>
              <size>1.4750311807091379 0.03 2.2</size>
            </box>
          </geometry>
          <material>
            <ambient>120 60 0 0.6</ambient>
            <diffuse>120 60 0 0.6</diffuse>
          </material>
        </visual>
        <collision name="right_collision">
          <geometry>
            <box>
              <size>1.4750311807091379 0.03 2.2</size>
            </box>
          </geometry>
          <surface>
            <contact>
              <collide_bitmask>0x02</collide_bitmask>
            </contact>
          </surface>
        </collision>
        <inertial>
          <mass>50.0</mass>
          <inertia>
            <ixx>20.17041666666667</ixx>
            <iyy>29.232154100267476</iyy>
            <izz>9.069237433600806</izz>
          </inertia>
        </inertial>
      </link>
      <joint name="right_joint" type="prismatic">
        <parent>world</parent>
        <child>right</child>
        <axis>
          <xyz>1 0 0</xyz>
          <limit>
            <lower>0.0</lower>
            <upper>1.4850311807091379</upper>
            <effort>500.0</effort>
          </limit>
        </axis>
      </joint>
      <plugin name="door" filename="libdoor.so">
        <v_max_door>0.2</v_max_door>
        <a_max_door>0.2</a_max_door>
        <a_nom_door>0.08</a_nom_door>
        <dx_min_door>0.001</dx_min_door>
        <f_max_door>100.0</f_max_door>
        <door name="main_door" type="DoubleSlidingDoor" left_joint_name="left_joint" right_joint_name="right_joint" />
      </plugin>
    </model>
    <model name="cafe_door_1">
      <pose>10.712818091016507 -24.998806025604672 0.0 0 0 -1.5807043503451461</pose>
      <link name="right">
        <pose>0 0 1.11 0 0 0</pose>
        <visual name="right_visual">
          <geometry>
            <box>
              <size>1.6561028754813483 0.03 2.2</size>
            </box>
          </geometry>
          <material>
            <ambient>120 60 0 0.6</ambient>
            <diffuse>120 60 0 0.6</diffuse>
          </material>
        </visual>
        <collision name="right_collision">
          <geometry>
            <box>
              <size>1.6561028754813483 0.03 2.2</size>
            </box>
          </geometry>
          <surface>
            <contact>
              <collide_bitmask>0x02</collide_bitmask>
            </contact>
          </surface>
        </collision>
        <inertial>
          <mass>50.0</mass>
          <inertia>
            <ixx>20.17041666666667</ixx>
            <iyy>31.59448639240663</iyy>
            <izz>11.43156972573996</izz>
          </inertia>
        </inertial>
      </link>
      <joint name="right_joint" type="prismatic">
        <parent>world</parent>
        <child>right</child>
        <axis>
          <xyz>1 0 0</xyz>
          <limit>
            <lower>0.0</lower>
            <upper>1.6661028754813483</upper>
            <effort>500.0</effort>
          </limit>
        </axis>
      </joint>
      <plugin name="door" filename="libdoor.so">
        <v_max_door>0.2</v_max_door>
        <a_max_door>0.2</a_max_door>
        <a_nom_door>0.08</a_nom_door>
        <dx_min_door>0.001</dx_min_door>
        <f_max_door>100.0</f_max_door>
        <door name="cafe_door_1" type="SlidingDoor" left_joint_name="empty_joint" right_joint_name="right_joint" />
      </plugin>
    </model>
    <model name="cafe_door_2">
      <pose>11.042496776425242 -13.14828105845325 0.0 0 0 1.5833281481840809</pose>
      <link name="right">
        <pose>0 0 1.11 0 0 0</pose>
        <visual name="right_visual">
          <geometry>
            <box>
              <size>1.3402145224496542 0.03 2.2</size>
            </box>
          </geometry>
          <material>
            <ambient>120 60 0 0.6</ambient>
            <diffuse>120 60 0 0.6</diffuse>
          </material>
        </visual>
        <collision name="right_collision">
          <geometry>
            <box>
              <size>1.3402145224496542 0.03 2.2</size>
            </box>
          </geometry>
          <surface>
            <contact>
              <collide_bitmask>0x02</collide_bitmask>
            </contact>
          </surface>
        </collision>
        <inertial>
          <mass>50.0</mass>
          <inertia>
            <ixx>20.17041666666667</ixx>
            <iyy>27.65072902577065</iyy>
            <izz>7.487812359103978</izz>
          </inertia>
        </inertial>
      </link>
      <joint name="right_joint" type="prismatic">
        <parent>world</parent>
        <child>right</child>
        <axis>
          <xyz>1 0 0</xyz>
          <limit>
            <lower>0.0</lower>
            <upper>1.3502145224496542</upper>
            <effort>500.0</effort>
          </limit>
        </axis>
      </joint>
      <plugin name="door" filename="libdoor.so">
        <v_max_door>0.2</v_max_door>
        <a_max_door>0.2</a_max_door>
        <a_nom_door>0.08</a_nom_door>
        <dx_min_door>0.001</dx_min_door>
        <f_max_door>100.0</f_max_door>
        <door name="cafe_door_2" type="SlidingDoor" left_joint_name="empty_joint" right_joint_name="right_joint" />
      </plugin>
    </model>
    <model name="stairs_door">
      <pose>9.504291021597032 -17.61334317179149 0.0 0 0 1.5588824943202708</pose>
      <link name="right">
        <pose>0 0 1.11 0 0 0</pose>
        <visual name="right_visual">
          <geometry>
            <box>
              <size>1.3013794263448157 0.03 2.2</size>
            </box>
          </geometry>
          <material>
            <ambient>120 60 0 0.6</ambient>
            <diffuse>120 60 0 0.6</diffuse>
          </material>
        </visual>
        <collision name="right_collision">
          <geometry>
            <box>
              <size>1.3013794263448157 0.03 2.2</size>
            </box>
          </geometry>
          <surface>
            <contact>
              <collide_bitmask>0x02</collide_bitmask>
            </contact>
          </surface>
        </collision>
        <inertial>
          <mass>50.0</mass>
          <inertia>
            <ixx>20.17041666666667</ixx>
            <iyy>27.223285047139846</iyy>
            <izz>7.060368380473174</izz>
          </inertia>
        </inertial>
      </link>
      <joint name="right_joint" type="prismatic">
        <parent>world</parent>
        <child>right</child>
        <axis>
          <xyz>1 0 0</xyz>
          <limit>
            <lower>0.0</lower>
            <upper>1.3113794263448157</upper>
            <effort>500.0</effort>
          </limit>
        </axis>
      </joint>
      <plugin name="door" filename="libdoor.so">
        <v_max_door>0.2</v_max_door>
        <a_max_door>0.2</a_max_door>
        <a_nom_door>0.08</a_nom_door>
        <dx_min_door>0.001</dx_min_door>
        <f_max_door>100.0</f_max_door>
        <door name="stairs_door" type="SlidingDoor" left_joint_name="empty_joint" right_joint_name="right_joint" />
      </plugin>
    </model>
    <model name="locker_rm_door">
      <pose>22.712426565987553 -11.284155025976462 0.0 0 0 3.0940125910372327</pose>
      <plugin name="door" filename="libdoor.so">
        <v_max_door>0.5</v_max_door>
        <a_max_door>0.3</a_max_door>
        <a_nom_door>0.15</a_nom_door>
        <dx_min_door>0.01</dx_min_door>
        <f_max_door>500.0</f_max_door>
        <door name="locker_rm_door" type="SwingDoor" left_joint_name="left_joint" right_joint_name="empty_joint" />
      </plugin>
      <link name="left">
        <pose>0 0 1.11 0 0 0</pose>
        <visual name="left_visual">
          <geometry>
            <box>
              <size>0.9122220675768421 0.03 2.2</size>
            </box>
          </geometry>
          <material>
            <ambient>120 60 0 0.6</ambient>
            <diffuse>120 60 0 0.6</diffuse>
          </material>
        </visual>
        <collision name="left_collision">
          <geometry>
            <box>
              <size>0.9122220675768421 0.03 2.2</size>
            </box>
          </geometry>
          <surface>
            <contact>
              <collide_bitmask>0x02</collide_bitmask>
            </contact>
          </surface>
        </collision>
        <inertial>
          <mass>50.0</mass>
          <inertia>
            <ixx>20.17041666666667</ixx>
            <iyy>23.633954585725707</iyy>
            <izz>3.4710379190590364</izz>
          </inertia>
        </inertial>
      </link>
      <joint name="left_joint" type="revolute">
        <parent>world</parent>
        <child>left</child>
        <axis>
          <xyz>0 0 1</xyz>
          <limit>
            <lower>-1.57</lower>
            <upper>0</upper>
          </limit>
        </axis>
        <pose>0.46111103378842105 0 0 0 0 0</pose>
      </joint>
    </model>
        
    <rmf_charger_waypoints name="charger_waypoints">
      <rmf_vertex name="tinyRobot1_charger" x="22.858547564160936" y="-12.49798808282204" level="L1" />
      <rmf_vertex name="tinyRobot2_charger" x="39.2263396653819" y="-12.45008680744747" level="L1" />
      <rmf_vertex name="Locust1_charger" x="26.302369225367293" y="-11.982747226039198" level="L1" />
      <rmf_vertex name="Locust2_charger" x="28.191801870095816" y="-25.216498898614642" level="L1" />
    </rmf_charger_waypoints>
  </world>
</sdf>
